[2024-10-01T16:30:17.453+0000] {taskinstance.py:1157} INFO - Dependencies all met for dep_context=non-requeueable deps ti=<TaskInstance: third_task_test.compare_and_trigger manual__2024-10-01T16:23:59.524388+00:00 [queued]>
[2024-10-01T16:30:17.468+0000] {taskinstance.py:1157} INFO - Dependencies all met for dep_context=requeueable deps ti=<TaskInstance: third_task_test.compare_and_trigger manual__2024-10-01T16:23:59.524388+00:00 [queued]>
[2024-10-01T16:30:17.469+0000] {taskinstance.py:1359} INFO - Starting attempt 2 of 2
[2024-10-01T16:30:17.487+0000] {taskinstance.py:1380} INFO - Executing <Task(PythonOperator): compare_and_trigger> on 2024-10-01 16:23:59.524388+00:00
[2024-10-01T16:30:17.515+0000] {standard_task_runner.py:57} INFO - Started process 93 to run task
[2024-10-01T16:30:17.524+0000] {standard_task_runner.py:84} INFO - Running: ['***', 'tasks', 'run', 'third_task_test', 'compare_and_trigger', 'manual__2024-10-01T16:23:59.524388+00:00', '--job-id', '84', '--raw', '--subdir', 'DAGS_FOLDER/data_fetching_huber_dag.py', '--cfg-path', '/tmp/tmp9zng163d']
[2024-10-01T16:30:17.525+0000] {standard_task_runner.py:85} INFO - Job 84: Subtask compare_and_trigger
[2024-10-01T16:30:17.647+0000] {task_command.py:415} INFO - Running <TaskInstance: third_task_test.compare_and_trigger manual__2024-10-01T16:23:59.524388+00:00 [running]> on host f6937622df26
[2024-10-01T16:30:17.771+0000] {taskinstance.py:1660} INFO - Exporting env vars: AIRFLOW_CTX_DAG_OWNER='***' AIRFLOW_CTX_DAG_ID='third_task_test' AIRFLOW_CTX_TASK_ID='compare_and_trigger' AIRFLOW_CTX_EXECUTION_DATE='2024-10-01T16:23:59.524388+00:00' AIRFLOW_CTX_TRY_NUMBER='2' AIRFLOW_CTX_DAG_RUN_ID='manual__2024-10-01T16:23:59.524388+00:00'
[2024-10-01T16:30:18.064+0000] {taskinstance.py:1935} ERROR - Task failed with exception
Traceback (most recent call last):
  File "/home/airflow/.local/lib/python3.8/site-packages/airflow/operators/python.py", line 192, in execute
    return_value = self.execute_callable()
  File "/home/airflow/.local/lib/python3.8/site-packages/airflow/operators/python.py", line 209, in execute_callable
    return self.python_callable(*self.op_args, **self.op_kwargs)
  File "/opt/airflow/dags/data_fetching_huber_dag.py", line 81, in compare_versions_and_create_trigger
    raise ValueError(f"bucket_name ({bucket_name}) or s3_key ({s3_key}) not set")
ValueError: bucket_name (None) or s3_key (None) not set
[2024-10-01T16:30:18.132+0000] {taskinstance.py:1398} INFO - Marking task as FAILED. dag_id=third_task_test, task_id=compare_and_trigger, execution_date=20241001T162359, start_date=20241001T163017, end_date=20241001T163018
[2024-10-01T16:30:18.154+0000] {standard_task_runner.py:104} ERROR - Failed to execute job 84 for task compare_and_trigger (bucket_name (None) or s3_key (None) not set; 93)
[2024-10-01T16:30:18.249+0000] {local_task_job_runner.py:228} INFO - Task exited with return code 1
[2024-10-01T16:30:18.335+0000] {taskinstance.py:2776} INFO - 0 downstream tasks scheduled from follow-on schedule check
