[2024-10-01T15:15:50.700+0000] {taskinstance.py:1157} INFO - Dependencies all met for dep_context=non-requeueable deps ti=<TaskInstance: sitemap_processing_pipeline.upload_to_s3 manual__2024-10-01T15:15:40.312692+00:00 [queued]>
[2024-10-01T15:15:50.714+0000] {taskinstance.py:1157} INFO - Dependencies all met for dep_context=requeueable deps ti=<TaskInstance: sitemap_processing_pipeline.upload_to_s3 manual__2024-10-01T15:15:40.312692+00:00 [queued]>
[2024-10-01T15:15:50.715+0000] {taskinstance.py:1359} INFO - Starting attempt 1 of 2
[2024-10-01T15:15:50.731+0000] {taskinstance.py:1380} INFO - Executing <Task(PythonOperator): upload_to_s3> on 2024-10-01 15:15:40.312692+00:00
[2024-10-01T15:15:50.738+0000] {standard_task_runner.py:57} INFO - Started process 190 to run task
[2024-10-01T15:15:50.743+0000] {standard_task_runner.py:84} INFO - Running: ['***', 'tasks', 'run', 'sitemap_processing_pipeline', 'upload_to_s3', 'manual__2024-10-01T15:15:40.312692+00:00', '--job-id', '44', '--raw', '--subdir', 'DAGS_FOLDER/data_fetching_huber_dag.py', '--cfg-path', '/tmp/tmp_itegvt_']
[2024-10-01T15:15:50.745+0000] {standard_task_runner.py:85} INFO - Job 44: Subtask upload_to_s3
[2024-10-01T15:15:50.820+0000] {task_command.py:415} INFO - Running <TaskInstance: sitemap_processing_pipeline.upload_to_s3 manual__2024-10-01T15:15:40.312692+00:00 [running]> on host f6937622df26
[2024-10-01T15:15:50.969+0000] {taskinstance.py:1660} INFO - Exporting env vars: AIRFLOW_CTX_DAG_OWNER='***' AIRFLOW_CTX_DAG_ID='sitemap_processing_pipeline' AIRFLOW_CTX_TASK_ID='upload_to_s3' AIRFLOW_CTX_EXECUTION_DATE='2024-10-01T15:15:40.312692+00:00' AIRFLOW_CTX_TRY_NUMBER='1' AIRFLOW_CTX_DAG_RUN_ID='manual__2024-10-01T15:15:40.312692+00:00'
[2024-10-01T15:15:51.155+0000] {taskinstance.py:1935} ERROR - Task failed with exception
Traceback (most recent call last):
  File "/home/airflow/.local/lib/python3.8/site-packages/airflow/operators/python.py", line 192, in execute
    return_value = self.execute_callable()
  File "/home/airflow/.local/lib/python3.8/site-packages/airflow/operators/python.py", line 209, in execute_callable
    return self.python_callable(*self.op_args, **self.op_kwargs)
  File "/opt/airflow/dags/data_fetching_huber_dag.py", line 67, in upload_to_s3_task
    s3.put_object(Body=json_data, Bucket=bucket_name, Key=s3_key_prefix)
  File "/home/airflow/.local/lib/python3.8/site-packages/botocore/client.py", line 535, in _api_call
    return self._make_api_call(operation_name, kwargs)
  File "/home/airflow/.local/lib/python3.8/site-packages/botocore/client.py", line 963, in _make_api_call
    http, parsed_response = self._make_request(
  File "/home/airflow/.local/lib/python3.8/site-packages/botocore/client.py", line 986, in _make_request
    return self._endpoint.make_request(operation_model, request_dict)
  File "/home/airflow/.local/lib/python3.8/site-packages/botocore/endpoint.py", line 119, in make_request
    return self._send_request(request_dict, operation_model)
  File "/home/airflow/.local/lib/python3.8/site-packages/botocore/endpoint.py", line 198, in _send_request
    request = self.create_request(request_dict, operation_model)
  File "/home/airflow/.local/lib/python3.8/site-packages/botocore/endpoint.py", line 134, in create_request
    self._event_emitter.emit(
  File "/home/airflow/.local/lib/python3.8/site-packages/botocore/hooks.py", line 412, in emit
    return self._emitter.emit(aliased_event_name, **kwargs)
  File "/home/airflow/.local/lib/python3.8/site-packages/botocore/hooks.py", line 256, in emit
    return self._emit(event_name, kwargs)
  File "/home/airflow/.local/lib/python3.8/site-packages/botocore/hooks.py", line 239, in _emit
    response = handler(**kwargs)
  File "/home/airflow/.local/lib/python3.8/site-packages/botocore/signers.py", line 105, in handler
    return self.sign(operation_name, request)
  File "/home/airflow/.local/lib/python3.8/site-packages/botocore/signers.py", line 189, in sign
    auth.add_auth(request)
  File "/home/airflow/.local/lib/python3.8/site-packages/botocore/auth.py", line 418, in add_auth
    raise NoCredentialsError()
botocore.exceptions.NoCredentialsError: Unable to locate credentials
[2024-10-01T15:15:51.168+0000] {taskinstance.py:1398} INFO - Marking task as UP_FOR_RETRY. dag_id=sitemap_processing_pipeline, task_id=upload_to_s3, execution_date=20241001T151540, start_date=20241001T151550, end_date=20241001T151551
[2024-10-01T15:15:51.181+0000] {standard_task_runner.py:104} ERROR - Failed to execute job 44 for task upload_to_s3 (Unable to locate credentials; 190)
[2024-10-01T15:15:51.215+0000] {local_task_job_runner.py:228} INFO - Task exited with return code 1
[2024-10-01T15:15:51.234+0000] {taskinstance.py:2776} INFO - 0 downstream tasks scheduled from follow-on schedule check
